Workbook

Sheet Summary
A1: Sitpur Banana + Multi-fruit Packhouse, Pre-cooling & Cold Storage – Unit Economics
A2: Farm: Sitpur Estate, Dabhoi, 150 acres (owner plan). Packhouse fruits: banana (own) + papaya + Kesar mango (procured). Prices & costs researched Sep-2026. All live formulas.
A4: Running days & capacity (change on Inputs)
B5: Packhouse | C5: Pre-cooling | D5: Cold storage
A6: Running days per year | B6: =Inputs!$B$8 -> 300 | C6: =Inputs!$B$9 -> 300 | D6: =Inputs!$B$10 -> 330 | F6: Estimates – edit on Inputs
A7: Utilisation | B7: ='Operations & Capacity'!$B$13 -> 0.75789474 | C7: ='Operations & Capacity'!$E$29 -> 0.58378947 | D7: ='Operations & Capacity'!$E$33 -> 0.86108421 | F7: Banana line / pre-cooling / cold-store peak
A8: Opex per year (₹) | B8: ='Packhouse Opex'!$B$37 -> 14210963 | C8: ='Packhouse Opex'!$B$38 -> 1806657.5 | D8: ='Packhouse Opex'!$B$39 -> 1526140
A9: Capex (₹) | B9: ='Packhouse Capex'!$E$10 -> 12250000 | C9: ='Packhouse Capex'!$E$13 -> 9000000 | D9: ='Packhouse Capex'!$E$16 -> 2200000
A10: Full cost per kg through (incl. depreciation & interest) | B10: ='Packhouse Opex'!$G$37 -> 2.090277 | C10: ='Packhouse Opex'!$G$38 -> 0.46815039 | D10: ='Packhouse Opex'!$G$39 -> 0.28644712
A12: Volumes (t/yr)
B13: Banana | C13: Papaya | D13: Mango | E13: Total
A14: Processed through packhouse | B14: ='Operations & Capacity'!$B$11 -> 5684.2105 | C14: ='Operations & Capacity'!$C$11 -> 1440 | D14: ='Operations & Capacity'!$D$11 -> 360 | E14: ='Operations & Capacity'!$E$11 -> 7484.2105
A15: Sellable packed | B15: ='Operations & Capacity'!$B$19 -> 4635.9284 | C15: ='Operations & Capacity'!$C$19 -> 1248.192 | D15: ='Operations & Capacity'!$D$19 -> 326.232 | E15: ='Operations & Capacity'!$E$19 -> 6210.3524
A16: Banana harvest / surplus sold at farm gate | B16: ='Farm Plan'!$D$40 -> 5684.2105 | C16: ='Operations & Capacity'!$B$12 -> 0 | F16: Col B harvest, col C unprocessed surplus
A17: Export containers per year | B17: ='Operations & Capacity'!$B$23 -> 57.891214
A19: Unit economics (₹ per kg sellable)
B20: Banana export | C20: Banana domestic | D20: Papaya | E20: Kesar mango
A21: Selling price | B21: ='Unit Economics'!$B$5 -> 51.692308 | C21: ='Unit Economics'!$C$5 -> 28 | D21: ='Unit Economics'!$D$5 -> 26 | E21: ='Unit Economics'!$E$5 -> 120
A22: Fruit cost (farm / procurement) | B22: ='Unit Economics'!$B$7 -> 8.9144159 | C22: ='Unit Economics'!$C$7 -> 8.9144159 | D22: ='Unit Economics'!$D$7 -> 14.997693 | E22: ='Unit Economics'!$E$7 -> 80.556169
A23: Pre-cooling | B23: ='Unit Economics'!$B$11 -> 0.29091062 | C23: ='Unit Economics'!$C$11 -> 0.29091062 | D23: ='Unit Economics'!$D$11 -> 0.29091062 | E23: ='Unit Economics'!$E$11 -> 0.29091062
A24: Cold storage | B24: ='Unit Economics'!$B$12 -> 0.24574129 | C24: ='Unit Economics'!$C$12 -> 0.24574129 | D24: ='Unit Economics'!$D$12 -> 0.24574129 | E24: ='Unit Economics'!$E$12 -> 0.24574129
A25: Packaging | B25: ='Unit Economics'!$B$13 -> 7.5384615 | C25: ='Unit Economics'!$C$13 -> 5.1538462 | D25: ='Unit Economics'!$D$13 -> 2 | E25: ='Unit Economics'!$E$13 -> 11.666667
A26: Freight (incl. ocean + surcharge for export) | B26: ='Unit Economics'!$B$15+'Unit Economics'!$B$17+'Unit Economics'!$B$18+'Unit Economics'!$B$16 -> 33.866134 | C26: ='Unit Economics'!$C$15+'Unit Economics'!$C$17+'Unit Economics'!$C$18+'Unit Economics'!$C$16 -> 4.7555556 | D26: ='Unit Economics'!$D$15+'Unit Economics'!$D$17+'Unit Economics'!$D$18+'Unit Economics'!$D$16 -> 2.8333333 | E26: ='Unit Economics'!$E$15+'Unit Economics'!$E$17+'Unit Economics'!$E$18+'Unit Economics'!$E$16 -> 4.7555556
A27: Total cost | B27: ='Unit Economics'!$B$25 -> 58.24593 | C27: ='Unit Economics'!$C$25 -> 25.160363 | D27: ='Unit Economics'!$D$25 -> 25.032471 | E27: ='Unit Economics'!$E$25 -> 106.21668
A28: Net margin | B28: ='Unit Economics'!$B$26 -> -6.5536227 | C28: ='Unit Economics'!$C$26 -> 2.8396367 | D28: ='Unit Economics'!$D$26 -> 0.96752918 | E28: ='Unit Economics'!$E$26 -> 13.783315
A29: Net margin % | B29: ='Unit Economics'!$B$27 -> -0.12678139 | C29: ='Unit Economics'!$C$27 -> 0.1014156 | D29: ='Unit Economics'!$D$27 -> 0.037212661 | E29: ='Unit Economics'!$E$27 -> 0.11486096
A30: Net margin per year (₹) | B30: ='Unit Economics'!$B$30 -> -7595531.5 | C30: ='Unit Economics'!$C$30 -> 9873264.3 | D30: ='Unit Economics'!$D$30 -> 1207662.2 | E30: ='Unit Economics'!$E$30 -> 4496558.4
A32: Annual P&L (₹ lakh)
B33: Sep-2026 conditions | C33: Normalised (no surcharge)
A34: Total revenue | B34: ='Annual P&L'!$B$13/100000 -> 2491.6069 | C34: ='Annual P&L'!$D$13/100000 -> 2491.6069
A35: Total operating cost | B35: ='Annual P&L'!$B$29/100000 -> 2273.165 | C35: ='Annual P&L'!$D$29/100000 -> 2050.8627
A36: EBITDA | B36: ='Annual P&L'!$B$30/100000 -> 218.44193 | C36: ='Annual P&L'!$D$30/100000 -> 440.74419
A37: Profit before tax | B37: ='Annual P&L'!$B$34/100000 -> 153.46334 | C37: ='Annual P&L'!$D$34/100000 -> 375.7656
A38: Packhouse business EBITDA (farm paid farm-gate price) | B38: ='Annual P&L'!$B$41/100000 -> -97.94702 | C38: ='Annual P&L'!$D$41/100000 -> 124.35524
A39: Net packhouse capex after subsidy | B39: ='Annual P&L'!$B$40/100000 -> 312.025 | C39: ='Annual P&L'!$D$40/100000 -> 312.025
A40: Payback on value added (years) | B40: ='Annual P&L'!$B$42 -> n/a | C40: ='Annual P&L'!$D$42 -> 2.5091423
A42: Rotation crop (per acre, before rent)
B43: Papaya | C43: Watermelon | D43: Green manure | E43: Banana (benchmark)
A44: Margin per acre per crop (₹) | B44: ='Crop Rotation'!$B$14 -> 360000 | C44: ='Crop Rotation'!$C$14 -> -20844 | D44: ='Crop Rotation'!$D$14 -> -5280
A45: Margin per acre per month (₹) | B45: ='Crop Rotation'!$B$15 -> 18000 | C45: ='Crop Rotation'!$C$15 -> -6948 | D45: ='Crop Rotation'!$D$15 -> -2640 | E45: ='Crop Rotation'!$B$16 -> 31578.947
...

Sheet Inputs
A1: Inputs & Assumptions – change blue cells; every tab recalculates
A2: Blue = input · Yellow = no reliable figure found, left blank · Confidence: User (your plan/DPR/notes) / Researched / Derived / Estimate. [S#] = Sources tab.
A4: Parameter | B4: Value | C4: Unit | D4: Low | E4: High | F4: Confidence | G4: Source / rationale
A5: General
A6: USD/INR exchange rate | B6: 96 | C6: ₹ per USD | D6: 95.5 | E6: 96.1 | F6: Researched | G6: [S1] 95.96 on 25-Sep-2026.
A7: RUNNING DAYS – drive capacity, labour and power (change these to test)
A8: Packhouse (grading/packing lines) running days per year | B8: 300 | C8: days/yr | D8: 250 | E8: 330 | F8: User | G8: Sitpur DPR design basis: 25 MT/day × ~300 operating days. Staggered banana planting keeps the line fed; ~65 days lost to Sundays/festivals/monsoon/maintenance.
A9: Pre-cooling running days per year | B9: 300 | C9: days/yr | D9: 250 | E9: 330 | F9: Estimate | G9: Runs whenever the packhouse packs fruit (same days as packhouse).
A10: Cold storage running days per year | B10: 330 | C10: days/yr | D10: 300 | E10: 365 | F10: Estimate | G10: Holds stock between packing and dispatch and during container build-up, so runs a little longer than the line; ~35 days shutdown for defrost/maintenance/lean weeks.
A11: Banana line intake capacity | B11: 25 | C11: t/day | D11: 20 | E11: 30 | F11: User | G11: Sitpur DPR: 25 MT/day design intake (planning figure).
A12: Multi-fruit line (papaya & mango) intake capacity | B12: 8 | C12: t/day | D12: 5 | E12: 12 | F12: Estimate | G12: Separate sorting/washing/sizing tables – papaya & mango are handled whole, not de-handed.
A13: Forced-air pre-cooling units | B13: 3 | C13: units | D13: 2 | E13: 4 | F13: Derived | G13: Sized in 'Operations & Capacity' – 3 × 6 MT covers banana + papaya/mango peaks.
A14: Pre-cooling batch size per unit | B14: 6 | C14: MT/batch | F14: Researched | G14: [S22] MIDH norm unit = 6 MT.
A15: Pre-cooling batches per unit per day | B15: 2 | C15: batches/day | D15: 2 | E15: 3 | F15: Estimate | G15: 6–8 h forced-air cycle.
A16: Cold storage capacity (2 chambers × 50 MT, 13 °C) | B16: 100 | C16: MT | D16: 50 | E16: 150 | F16: Derived | G16: Two chambers so ethylene-producing papaya/mango never share air with green banana. DPR had 20–25 MT – too small once export containers (20 t each) are staged.
A17: Average cold-storage holding – banana | B17: 2 | C17: days | D17: 1 | E17: 4 | F17: Estimate
A18: Average cold-storage holding – papaya | B18: 3 | C18: days | D18: 2 | E18: 7 | F18: Estimate
A19: Average cold-storage holding – mango | B19: 4 | C19: days | D19: 2 | E19: 10 | F19: Estimate
A20: Farm – Sitpur Estate, Dabhoi (owner business plan, Sep-2026)
A21: Area under banana | B21: 150 | C21: acres | F21: User | G21: Farm plan.
A22: Plants per acre (6 ft × 6 ft) | B22: 1200 | C22: plants/acre | D22: 1200 | E22: 1452 | F22: User | G22: Farm plan. Research: 1,200–1,450 [S2].
A23: Yield per plant – plant crop | B23: 25 | C23: kg/plant | D23: 20 | E23: 30 | F23: User | G23: Farm plan ('minimum'). = 30 t/acre; Gujarat avg 26.7 t/acre [S4].
A24: Yield per plant – ratoon | B24: 25 | C24: kg/plant | D24: 18 | E24: 25 | F24: User | G24: Farm plan. Plan itself flags ratoon bunches are often lighter – test ~20 kg.
A25: Plant-crop months (planting → harvest) | B25: 11 | C25: months | D25: 11 | E25: 13 | F25: User | G25: Farm plan.
A26: Ratoon months | B26: 8 | C26: months | D26: 8 | E26: 10 | F26: User | G26: Farm plan (19-month cycle, then replant).
A27: Inputs per plant – plant crop (plant, fertiliser, pesticide, labour) | B27: 125 | C27: ₹/plant | F27: User | G27: Farm plan (plant material ₹17–20 included).
A28: Inputs per plant – ratoon | B28: 50 | C28: ₹/plant | F28: User | G28: Farm plan.
A29: Land rent (opportunity cost) | B29: 50000 | C29: ₹/acre/yr | D29: 30000 | E29: 80000 | F29: User | G29: Farm plan; research range ₹30,000–80,000 [S5].
A30: Farm-gate price – plant crop (used for surplus sold unprocessed) | B30: 15 | C30: ₹/kg | D30: 8 | E30: 21 | F30: User | G30: Farm plan; your draft ₹11–21 seasonal.
A31: Farm-gate price – ratoon | B31: 12 | C31: ₹/kg | D31: 8 | E31: 20 | F31: User | G31: Farm plan.
A32: SCENARIO: banana yield shortfall this season | B32: 0 | C32: % of yield | D32: 0 | E32: 0.5 | F32: Scenario | G32: Set e.g. 30% to test a bad season (disease, wind, heat).
A33: SCENARIO: acres switched to rotation crop | B33: 0 | C33: acres | D33: 0 | E33: 150 | F33: Scenario | G33: Acres taken out of banana this year and planted with the crop chosen on 'Crop Rotation'.
A34: Rotation crop chosen (1 = Papaya, 2 = Watermelon, 3 = Green manure) | B34: 1 | C34: choice | D34: 1 | E34: 3 | F34: Derived | G34: Papaya recommended – see 'Crop Rotation'.
A35: LABOUR – daily-wage cap
A36: Upper limit – loading/unloading & harvest labour | B36: 1000 | C36: ₹/person/day | F36: User | G36: Your instruction: never above ₹1,000/day. All harvest & loading wages below are capped with MIN(rate, cap).
A37: Harvest tonnes per crew-day | B37: 13 | C37: t/crew-day | F37: User | G37: Your note: 13 t needs 10 people + 3 harvesters.
A38: Harvest carriers / handlers per crew | B38: 10 | C38: people | F38: User | G38: Your note.
A39: Harvesters (bunch cutters) per crew | B39: 3 | C39: people | F39: User | G39: Your note.
A40: Harvest wage asked | B40: 1000 | C40: ₹/person/day | F40: User | G40: Your note – at the cap.
A41: Loading / unloading crew at packhouse | B41: 8 | C41: people/day | D41: 6 | E41: 12 | F41: Estimate | G41: Unloading field crates & procured fruit, loading reefer trucks/containers.
...

Sheet Farm Plan
A1: Farm economics – Sitpur Estate, 150 acres (from your Banana Farm Business Plan, Sep-2026)
A2: Owner figures are the base case (Confidence = User). Research cross-checks are shown alongside. Harvest labour is costed in 'Packhouse Opex' with the ₹1,000/day cap.
A4: Item | B4: Plant crop | C4: Ratoon | D4: Full cycle / annual | E4: Basis | F4: Research cross-check
A5: A. Per acre (owner plan)
A6: Months | B6: =Inputs!$B$25 -> 11 | C6: =Inputs!$B$26 -> 8 | D6: =B6+C6 -> 19 | E6: 19-month cycle, then replant | F6: [S2] G9 matures 11–12 months in Gujarat
A7: Output (kg/acre) | B7: =Inputs!$B$22*Inputs!$B$23*(1-Inputs!$B$32) -> 30000 | C7: =Inputs!$B$22*Inputs!$B$24*(1-Inputs!$B$32) -> 30000 | D7: =B7+C7 -> 60000 | E7: Plants × kg/plant × (1 − shortfall) | F7: [S4] Gujarat avg 26.7 t/acre; Bharuch 29.4 t/acre
A8: Inputs (₹/acre) | B8: =Inputs!$B$22*Inputs!$B$27 -> 150000 | C8: =Inputs!$B$22*Inputs!$B$28 -> 60000 | D8: =B8+C8 -> 210000 | E8: ₹125 / ₹50 per plant (plant, fertiliser, pesticide, labour) | F8: Researched itemised build-up (v1 of this workbook) gave ₹1.64 L plant crop excl. rent – plan's ₹1.5 L is consistent
A9: Farm-gate value (₹/acre) – reference only | B9: =B7*Inputs!$B$30 -> 450000 | C9: =C7*Inputs!$B$31 -> 360000 | D9: =B9+C9 -> 810000 | E9: What the fruit is worth if sold at farm gate
A10: Plan's harvest handling ₹10/plant (NOT used – see note) | B10: =Inputs!$B$22*10 -> 12000 | C10: =Inputs!$B$22*10 -> 12000 | E10: Replaced by your crew model (13 people/13 t, ≤₹1,000/day) = ~₹1/kg vs ₹0.40/kg here
A12: B. Annual farm fixed costs (owner plan)
A13: Item | B13: Qty | C13: Rate (₹) | D13: ₹ per year | E13: Basis | F13: Note
A14: Permanent workers already inside ₹125/₹50 per-plant inputs? (1 = yes → exclude below) | B14: 0 | E14: Plan's open question; base case counts them
A15: Land rent | B15: =Inputs!$B$21 -> 150 | C15: =Inputs!$B$29 -> 50000 | D15: =B15*C15 -> 7500000 | E15: 150 acres × ₹50,000 | F15: Opportunity cost if owners farm it
A16: Farm workers (50 × 312 paid days) | B16: 50 | C16: 400 | D16: =IF($B$14=1,0,B16*C16*312) -> 6240000 | E16: ₹400/day | F16: Below Gujarat minimum wage (₹501–512/day, [S6]) – check
A17: Agronomist / farm manager | B17: 1 | C17: 60000 | D17: =B17*C17*12 -> 720000 | E17: ₹/month
A18: Sub-assistants | B18: 2 | C18: 25000 | D18: =B18*C18*12 -> 600000 | E18: ₹/month
A19: GAS – salary | B19: 1 | C19: 25000 | D19: =B19*C19*12 -> 300000 | E19: ₹/month
A20: HAS – salary | B20: 1 | C20: 25000 | D20: =B20*C20*12 -> 300000 | E20: ₹/month
A21: Company driver | B21: 1 | C21: 18000 | D21: =B21*C21*12 -> 216000 | E21: ₹/month
A22: MGVCL power, 9 connections | B22: 9 | C22: 30000 | D22: =B22*C22 -> 270000 | E22: ₹/connection/yr
A23: Fuel – tractors | B23: 1 | C23: 1200000 | D23: =B23*C23 -> 1200000 | E23: ₹/yr
A24: Fuel – car & 3 bikes | B24: 12 | C24: 29000 | D24: =B24*C24 -> 348000 | E24: ₹/month
A25: Repairs & maintenance | B25: 1 | C25: 300000 | D25: =B25*C25 -> 300000 | E25: ₹/yr
A26: Insurance – vehicles, assets, staff accident | B26: 1 | C26: 400000 | D26: =B26*C26 -> 400000 | E26: ₹/yr
A27: Crop insurance (5% of ₹1.5 L/acre) | B27: =Inputs!$B$21 -> 150 | C27: 7500 | D27: =B27*C27 -> 1125000 | E27: ₹/acre/yr | F27: Gujarat exited PMFBY – private/state policy quote needed
A28: Total farm fixed costs | D28: =SUM(D15:D27) -> 19519000 | E28: Plan: ₹195.19 L
A30: C. Farm capex (owner plan)
A31: Asset | B31: Cost (₹) | C31: Life (yrs) | D31: Depreciation ₹/yr | E31: Note
A32: Tractors: 3 large @ ₹10 L + 3 small @ ₹6 L | B32: 4800000 | C32: 8 | D32: =B32/C32 -> 600000
A33: Drip irrigation @ ₹50,000/acre + headworks | B33: 8000000 | C33: 7 | D33: =B33/C33 -> 1142857.1 | E33: Research: ₹25,000–60,000/acre [S8]
A34: 50-t truck weighbridge incl. civil | B34: 700000 | C34: 10 | D34: =B34/C34 -> 70000
A35: Wild boar / animal fencing | B35: 300000 | C35: 3 | D35: =B35/C35 -> 100000
A36: Total farm capex / depreciation | B36: =SUM(B32:B35) -> 13800000 | D36: =SUM(D32:D35) -> 1912857.1
A38: D. Annual farm summary (banana acres = 150 − rotation acres)
A39: Banana acres this year | D39: =(Inputs!$B$21-Inputs!$B$33) -> 150
A40: Annual banana harvest (t) | D40: =(Inputs!$B$21-Inputs!$B$33)*D7/D6*12/1000 -> 5684.2105
A41: Annual inputs (₹) | D41: =(Inputs!$B$21-Inputs!$B$33)*D8/D6*12 -> 19894737
A42: Annual fixed costs (₹) | D42: =D28 -> 19519000
A43: Farm cash cost (inputs + fixed) (₹) | D43: =D41+D28 -> 39413737
A44: Farm depreciation (₹) | D44: ='Farm Plan'!$D$36 -> 1912857.1
...

Sheet Crop Rotation
A1: Rotation / backup crop for seasons when banana does not do well
A2: Compared per acre. Land rent is already in farm fixed costs, so margins here are before rent. Pick the crop on Inputs → 'Rotation crop chosen' and set acres to switch.
A4: Item | B4: 1. Papaya (Red Lady 786) | C4: 2. Watermelon (hybrid) | D4: 3. Green manure (sunhemp / dhaincha) | E4: Unit | F4: Sources / notes
A5: Duration in field | B5: 20 | C5: 3 | D5: 2 | E5: months | F5: Papaya fruits from 6–8 months and bears ~2 years [S39]; watermelon 75–90 days [S40]; green manure 45–60 days [S41].
A6: Cultivation cost (excl. land rent) | B6: 80000 | C6: 82844 | D6: =D7+D8 -> 5280 | E6: ₹/acre | F6: [S39] papaya ₹70–90k/acre; [S40] watermelon Banaskantha study ₹2,04,696/ha (cost C2). Green manure computed below.
A7: Green manure: seed 20 kg × price | D7: =20*114 -> 2280 | E7: ₹/acre | F7: [S41] 20 kg/acre; dhaincha seed ₹2,850/25 kg (≈₹114/kg).
A8: Green manure: sowing + incorporation | D8: 3000 | E8: ₹/acre | F8: Estimate (tractor passes).
A9: Yield | B9: 40 | C9: 10 | D9: 0 | E9: t/acre | F9: [S39] papaya 30–50 t/acre over its life; [S40] watermelon 8–12 t/acre.
A10: Farm-gate price | B10: 12 | C10: 7 | D10: 0 | E10: ₹/kg | F10: [S34] papaya ₹10–20/kg Gujarat 2026; [S40] watermelon ₹4–6.25/kg Gujarat mandis (May-2025), +20–30% in 2026 [S42].
A11: Harvest & transport to buyer | B11: 1 | C11: 0.8 | D11: 0 | E11: ₹/kg | F11: Estimate.
A12: Revenue per acre | B12: =B9*1000*B10 -> 480000 | C12: =C9*1000*C10 -> 70000 | D12: =D9*1000*D10 -> 0
A13: Harvest & transport | B13: =B9*1000*B11 -> 40000 | C13: =C9*1000*C11 -> 8000 | D13: =D9*1000*D11 -> 0
A14: Margin per acre per crop (before rent) | B14: =B12-B6-B13 -> 360000 | C14: =C12-C6-C13 -> -20844 | D14: =D12-D6-D13 -> -5280
A15: Margin per acre per month in field | B15: =B14/B5 -> 18000 | C15: =C14/C5 -> -6948 | D15: =D14/D5 -> -2640
A16: Banana benchmark: margin per acre per month (farm-gate value − inputs) | B16: =('Farm Plan'!$D$9-'Farm Plan'!$D$8)/'Farm Plan'!$D$6 -> 31578.947 | F16: From 'Farm Plan' section A (before harvest labour and fixed costs)
A18: Agronomic fit
A19: Breaks the banana disease cycle (Fusarium wilt, nematodes)? | B19: Yes – not a host of Foc [S43] | C19: Yes – cucurbits are among rotation crops shown to cut banana wilt [S43] | D19: Yes – adds organic matter; best done just before replanting
A20: Reuses banana drip, labour & packhouse? | B20: Yes – drip reused; fruit goes through your own multi-fruit line | C20: Partly – drip reused; sold direct (low value/kg for packhouse) | D20: No revenue
A21: Key risk | B21: Papaya ringspot virus (aphids); keep away from cucurbits | C21: Hosts papaya ringspot virus-W – don't grow next to papaya | D21: None
A22: When to use | B22: Main backup: a whole block that fails or needs a 1.5–2 yr break | C22: Quick 3-month filler if a failure is noticed in Dec–Feb, before June replanting | D22: 45–60 days before every banana replant
A24: Scenario feeding the P&L (from Inputs)
A25: Crop chosen | B25: =INDEX(B4:D4,1,Inputs!$B$34) -> 1. Papaya (Red Lady 786)
A26: Acres switched out of banana | B26: =Inputs!$B$33 -> 0
A27: Annualised rotation-crop revenue (₹) | B27: =B26*INDEX(B12:D12,1,Inputs!$B$34)/INDEX(B5:D5,1,Inputs!$B$34)*12 -> 0
A28: Annualised rotation-crop cost (₹) | B28: =B26*(INDEX(B6:D6,1,Inputs!$B$34)+INDEX(B13:D13,1,Inputs!$B$34))/INDEX(B5:D5,1,Inputs!$B$34)*12 -> 0
A29: Recommendation
A30: Use papaya as the backup cash crop, because it is the only option that comes close to banana's margin per acre-month and it feeds your own packhouse. Sow green manure before every banana replant. Use watermelon only as a short filler, and never next to papaya. Rotation cuts Fusarium wilt risk, which the plan lists as a key threat on land that has been under banana since 2010.

Sheet Fruit Selection
A1: Which extra fruits should the packhouse handle? (screening of candidates)
A2: Criteria: supply near Sitpur, season that fills banana gaps, storage compatible with banana's 13–14 °C rooms, value per kg, fit with lines. Blank = not verified.
A4: Fruit | B4: Supply near Sitpur | C4: Season | D4: Storage temp & shelf life | E4: Buy price (₹/kg, 2026) | F4: Premium sale / retail (₹/kg) | G4: Fit with banana packhouse | H4: Verdict
A5: Papaya | B5: Anand & Vadodara have the largest papaya area in Middle Gujarat [S34] | C5: Almost year-round | D5: 10–13 °C; 1–3 weeks; tropical group with banana & mango [S44] | E5: 10–20 [S34] | F5: BigBasket 61–81 retail [S35] | G5: Same 13 °C chamber group; high volume fills idle line capacity | H5: RECOMMENDED
A6: Kesar mango | B6: Valsad/Navsari ~150–200 km; Gir-Talala ~400 km [S37] | C6: Apr–Jun (~60 days) | D6: 12–13 °C; 2–3 weeks; tropical group [S44] | E6: 70–75 APMC; 40–133 by grade [S38] | F6: 140–150 dealer; 407 BigBasket [S35][S38] | G6: Highest value per kg; pre-cooling adds shelf life; short season | H6: RECOMMENDED (seasonal)
A7: Sapota (chikoo) | B7: Navsari/Valsad – India's largest sapota belt, ~150 km [S45] | C7: Most of the year (peak winter) | E7: 7.5–12.5 Valsad APMC [S45] | F7: ~35 Gujarat market [S45] | G7: Low value; ~90% already flows to Delhi via co-ops | H7: Possible later
A8: Pomegranate | B8: Kutch/Banaskantha ~400–450 km [S46] | C8: Main crop in winter | D8: ~5–7 °C – needs its own chamber (standard post-harvest guides) | E8: 30 (A-grade, Kutch) [S46] | F8: 115 wholesale; 132–150 export grade [S46] | G8: Separate cold room; export needs registered farms (Anar-Net); far away | H8: Not now
A9: Watermelon | B9: Mahuva/Bhavnagar & local [S42] | C9: Feb–May | E9: 4–6 [S40] | G9: Bulky, low value per kg – packing adds little | H9: Rotation crop only
A11: Decision: banana + papaya + Kesar mango. All three are tropical, chilling-sensitive fruit stored around 13 °C, so they share pre-cooling. Papaya and mango give off ethylene, which would ripen green banana, so they get their own 50 MT cold chamber. Pomegranate would need a third, colder chamber.
A13: Operating calendar (● = packing that fruit)
A14: Fruit | B14: Jan | C14: Feb | D14: Mar | E14: Apr | F14: May | G14: Jun | H14: Jul | I14: Aug | J14: Sep | K14: Oct | L14: Nov | M14: Dec
A15: Banana | B15: ● | C15: ● | D15: ● | E15: ● | F15: ● | G15: ● | H15: ● | I15: ● | J15: ● | K15: ● | L15: ● | M15: ●
A16: Papaya | B16: ● | C16: ● | D16: ● | H16: ● | I16: ● | J16: ● | K16: ● | L16: ● | M16: ●
A17: Mango | E17: ● | F17: ● | G17: ●

Sheet Operations & Capacity
A1: Operations, running days, capacity & volumes
A2: Everything here recalculates from the running days on Inputs. If days fall, capacity falls and unprocessed banana is sold at farm gate.
A4: Item | B4: Banana | C4: Papaya | D4: Mango | E4: Total | F4: Unit / note
A5: Running days & capacity
A6: Packing days used | B6: =Inputs!$B$8 -> 300 | C6: =MAX(0,MIN(Inputs!$B$76,Inputs!$B$8-D6)) -> 240 | D6: =MIN(Inputs!$B$86,Inputs!$B$8) -> 60 | F6: days/yr – mango gets priority in its season, papaya fills the rest
A7: Line capacity per day | B7: =Inputs!$B$11 -> 25 | C7: =MIN(Inputs!$B$75,Inputs!$B$12) -> 6 | D7: =MIN(Inputs!$B$85,Inputs!$B$12) -> 6 | F7: t/day intake
A8: Line capacity per year | B8: =B6*B7 -> 7500 | C8: =C6*C7 -> 1440 | D8: =D6*D7 -> 360 | F8: t/yr
A9: Intake
A10: Fruit available (banana harvest / planned procurement) | B10: ='Farm Plan'!$D$40 -> 5684.2105 | C10: =Inputs!$B$75*Inputs!$B$76 -> 1440 | D10: =Inputs!$B$85*Inputs!$B$86 -> 360 | F10: t/yr
A11: Processed through packhouse | B11: =MIN(B10,B8) -> 5684.2105 | C11: =MIN(C10,C8) -> 1440 | D11: =MIN(D10,D8) -> 360 | E11: =SUM(B11:D11) -> 7484.2105 | F11: t/yr
A12: Banana not processed → sold at farm gate | B12: =B10-B11 -> 0 | F12: t/yr – rises if you cut running days
A13: Line utilisation | B13: =IF(B8=0,0,B11/B8) -> 0.75789474 | C13: =IF(C8=0,0,C11/C8) -> 1 | D13: =IF(D8=0,0,D11/D8) -> 1 | F13: %
A14: Mass balance
A15: Stalk / rachis removed | B15: =B11*Inputs!$B$58 -> 454.73684 | C15: 0 | D15: 0 | E15: =SUM(B15:D15) -> 454.73684 | F15: t/yr → compost
A16: Fruit after de-handing / receiving | B16: =B11-B15 -> 5229.4737 | C16: =C11 -> 1440 | D16: =D11 -> 360 | E16: =SUM(B16:D16) -> 7029.4737 | F16: t/yr
A17: Culls / B-grade | B17: =B16*Inputs!$B$59 -> 522.94737 | C17: =C16*Inputs!$B$79 -> 172.8 | D17: =D16*Inputs!$B$89 -> 28.8 | E17: =SUM(B17:D17) -> 724.54737 | F17: t/yr → banana flour; papaya & mango → compost
A18: Graded fruit to pre-cooling | B18: =B16-B17 -> 4706.5263 | C18: =C16-C17 -> 1267.2 | D18: =D16-D17 -> 331.2 | E18: =SUM(B18:D18) -> 6304.9263 | F18: t/yr
A19: Sellable packed fruit | B19: =B18*(1-Inputs!$B$60) -> 4635.9284 | C19: =C18*(1-Inputs!$B$60) -> 1248.192 | D19: =D18*(1-Inputs!$B$60) -> 326.232 | E19: =SUM(B19:D19) -> 6210.3524 | F19: t/yr
A20: of which export | B20: =B19*Inputs!$B$61 -> 1158.9821 | C20: 0 | D20: 0 | E20: =SUM(B20:D20) -> 1158.9821 | F20: t/yr
A21: of which domestic premium | B21: =B19-B20 -> 3476.9463 | C21: =C19 -> 1248.192 | D21: =D19 -> 326.232 | E21: =SUM(B21:D21) -> 5051.3703 | F21: t/yr
A22: Cartons / boxes | B22: =B19*1000/Inputs!$B$62 -> 356609.88 | C22: =C19*1000/Inputs!$B$81 -> 124819.2 | D22: =D19*1000/Inputs!$B$91 -> 108744 | E22: =SUM(B22:D22) -> 590173.08 | F22: per year
A23: Export containers (40' HC) | B23: =B20*1000/(Inputs!$B$62*Inputs!$B$63) -> 57.891214 | F23: per year
A24: Domestic reefer trips | B24: =B21*1000/Inputs!$B$109 -> 386.32737 | C24: =C21*1000/Inputs!$B$109 -> 138.688 | D24: =D21*1000/Inputs!$B$109 -> 36.248 | E24: =SUM(B24:D24) -> 561.26337 | F24: per year
A25: Pseudostem biomass (whole harvest) | B25: =(Inputs!$B$21-Inputs!$B$33)*Inputs!$B$22*Inputs!$B$64*24/(Inputs!$B$25+Inputs!$B$26)/1000 -> 6821.0526 | F25: t/yr
A26: Pre-cooling check
A27: Average pre-cooling load on running days | E27: =E18/Inputs!$B$9 -> 21.016421 | F27: t/day
A28: Pre-cooling capacity | E28: =Inputs!$B$13*Inputs!$B$14*Inputs!$B$15 -> 36 | F28: t/day
A29: Pre-cooling utilisation | E29: =E27/E28 -> 0.58378947 | F29: % – above ~80% means peaks will overflow; add a unit
A30: Cold storage check
A31: Average stock held (t) | B31: =B18*Inputs!$B$17/Inputs!$B$10 -> 28.524402 | C31: =C18*Inputs!$B$18/Inputs!$B$10 -> 11.52 | D31: =D18*Inputs!$B$19/Inputs!$B$10 -> 4.0145455 | E31: =SUM(B31:D31) -> 44.058947 | F31: t – banana chamber vs papaya/mango chamber
A32: Peak stock incl. one export container being built (t) | B32: =B31*1.5+IF(B20>0,Inputs!$B$62*Inputs!$B$63/1000,0) -> 62.806603 | C32: =C31*1.5 -> 17.28 | D32: =D31*1.5 -> 6.0218182 | E32: =SUM(B32:D32) -> 86.108421 | F32: t (×1.5 peak factor)
A33: Peak utilisation of 100 MT | E33: =E32/Inputs!$B$16 -> 0.86108421 | F33: %
A34: Labour days
A35: Harvest crew-days (whole banana harvest) | B35: ='Farm Plan'!$D$40/Inputs!$B$37 -> 437.24696 | F35: crew-days/yr (13 people each)
A36: Multi-fruit line days | E36: =C6+D6 -> 300 | F36: days/yr

Sheet Packhouse Capex
A1: Capex by cost centre – packhouse lines, PRE-COOLING, COLD STORAGE and common services
A2: Market prices vs MIDH norms; subsidy on the lower of the two. DPR comparison at the bottom.
A4: Item | B4: Qty | C4: Unit | D4: Unit cost (₹) | E4: Amount (₹) | F4: MIDH norm cap (₹) | G4: Subsidy-eligible (₹) | H4: Subsidy (₹) | I4: Life (yrs) | J4: Depreciation (₹/yr) | K4: Confidence | L4: Source / note
A5: A. PACKHOUSE LINES
A6: Integrated banana pack house (PEB shed, de-handing & wash tanks, conveyor, grading, weighing) | B6: 1 | C6: unit | D6: 9000000 | E6: =B6*D6 -> 9000000 | F6: =B6*5000000 -> 5000000 | G6: =IF(ISNUMBER(F6),MIN(E6,F6),0) -> 5000000 | H6: =G6*Inputs!$B$119 -> 1750000 | I6: 15 | J6: =E6/I6 -> 600000 | K6: Researched | L6: [S24] ₹90 L listing; MIDH norm ₹50 L [S22].
A7: Multi-fruit line: sorting tables, washer/brusher, roller sizer, wrapping tables (papaya & mango) | B7: 1 | C7: lot | D7: 1800000 | E7: =B7*D7 -> 1800000 | F7: not eligible | G7: =IF(ISNUMBER(F7),MIN(E7,F7),0) -> 0 | H7: =G7*Inputs!$B$119 -> 0 | I7: 10 | J7: =E7/I7 -> 180000 | K7: Estimate | L7: Get vendor quotes.
A8: Plastic field crates (banana + papaya + mango) | B8: 3000 | C8: crates | D8: 350 | E8: =B8*D8 -> 1050000 | F8: not eligible | G8: =IF(ISNUMBER(F8),MIN(E8,F8),0) -> 0 | H8: =G8*Inputs!$B$119 -> 0 | I8: 4 | J8: =E8/I8 -> 262500 | K8: Estimate
A9: Material handling: pallet trucks, scales, carton sealing | B9: 1 | C9: lot | D9: 400000 | E9: =B9*D9 -> 400000 | F9: not eligible | G9: =IF(ISNUMBER(F9),MIN(E9,F9),0) -> 0 | H9: =G9*Inputs!$B$119 -> 0 | I9: 7 | J9: =E9/I9 -> 57142.857 | K9: Estimate
A10: Subtotal – Packhouse Lines | E10: =SUM(E6:E9) -> 12250000 | G10: =SUM(G6:G9) -> 5000000 | H10: =SUM(H6:H9) -> 1750000 | J10: =SUM(J6:J9) -> 1099642.9
A11: B. PRE-COOLING
A12: Forced-air pre-cooling units, 6 MT/batch | B12: =Inputs!$B$13 -> 3 | C12: unit | D12: 3000000 | E12: =B12*D12 -> 9000000 | F12: =B12*2500000 -> 7500000 | G12: =IF(ISNUMBER(F12),MIN(E12,F12),0) -> 7500000 | H12: =G12*Inputs!$B$119 -> 2625000 | I12: 10 | J12: =E12/I12 -> 900000 | K12: Derived | L12: MIDH norm ₹25 L per 6 MT unit [S22]; market ~20% above.
A13: Subtotal – Pre-Cooling | E13: =SUM(E12:E12) -> 9000000 | G13: =SUM(G12:G12) -> 7500000 | H13: =SUM(H12:H12) -> 2625000 | J13: =SUM(J12:J12) -> 900000
A14: C. COLD STORAGE
A15: Cold chambers at 13 °C (2 × 50 MT, insulated panels, refrigeration) | B15: =Inputs!$B$16 -> 100 | C15: MT | D15: 22000 | E15: =B15*D15 -> 2200000 | F15: =B15*8000 -> 800000 | G15: =IF(ISNUMBER(F15),MIN(E15,F15),0) -> 800000 | H15: =G15*Inputs!$B$119 -> 280000 | I15: 10 | J15: =E15/I15 -> 220000 | K15: Researched | L15: [S25] ₹14–18k/MT at scale; small chambers cost more. MIDH ~₹8,000/MT.
A16: Subtotal – Cold Storage | E16: =SUM(E15:E15) -> 2200000 | G16: =SUM(G15:G15) -> 800000 | H16: =SUM(H15:H15) -> 280000 | J16: =SUM(J15:J15) -> 220000
A17: D. COMMON SERVICES
A18: Site development (3–5 acre carve-out at Sitpur) | B18: 1 | C18: lot | D18: 1000000 | E18: =B18*D18 -> 1000000 | F18: not eligible | G18: =IF(ISNUMBER(F18),MIN(E18,F18),0) -> 0 | H18: =G18*Inputs!$B$119 -> 0 | I18: 20 | J18: =E18/I18 -> 50000 | K18: Estimate | L18: DPR: site within Sitpur Estate.
A19: Electrical: transformer / HT connection, panels | B19: 1 | C19: lot | D19: 1200000 | E19: =B19*D19 -> 1200000 | F19: not eligible | G19: =IF(ISNUMBER(F19),MIN(E19,F19),0) -> 0 | H19: =G19*Inputs!$B$119 -> 0 | I19: 15 | J19: =E19/I19 -> 80000 | K19: Estimate | L19: DPR: 3-phase available at estate office – extension needed.
A20: DG set 160 kVA (backup for refrigeration) | B20: 1 | C20: unit | D20: 1400000 | E20: =B20*D20 -> 1400000 | F20: not eligible | G20: =IF(ISNUMBER(F20),MIN(E20,F20),0) -> 0 | H20: =G20*Inputs!$B$119 -> 0 | I20: 10 | J20: =E20/I20 -> 140000 | K20: Estimate
A21: Water: borewell link, storage, filtration, wash-water treatment | B21: 1 | C21: lot | D21: 800000 | E21: =B21*D21 -> 800000 | F21: not eligible | G21: =IF(ISNUMBER(F21),MIN(E21,F21),0) -> 0 | H21: =G21*Inputs!$B$119 -> 0 | I21: 10 | J21: =E21/I21 -> 80000 | K21: Estimate | L21: DPR: 9 borewells on estate.
A22: QC lab + office & IT | B22: 1 | C22: lot | D22: 300000 | E22: =B22*D22 -> 300000 | F22: not eligible | G22: =IF(ISNUMBER(F22),MIN(E22,F22),0) -> 0 | H22: =G22*Inputs!$B$119 -> 0 | I22: 5 | J22: =E22/I22 -> 60000 | K22: Estimate
A23: Subtotal – Common Services | E23: =SUM(E18:E22) -> 4700000 | G23: =SUM(G18:G22) -> 0 | H23: =SUM(H18:H22) -> 0 | J23: =SUM(J18:J22) -> 410000
A24: Contingency & pre-operative (5%) – common | B24: 0.05 | E24: =(E10+E13+E16+E23)*B24 -> 1407500 | G24: 0 | H24: 0 | I24: 10 | J24: =E24/I24 -> 140750
A25: TOTAL PROJECT COST | E25: =E10+E13+E16+E23+E24 -> 29557500 | G25: =G10+G13+G16+G23+G24 -> 13300000 | H25: =H10+H13+H16+H23+H24 -> 4655000 | J25: =J10+J13+J16+J23+J24 -> 2770392.9
A27: Financing (AIF + MIDH)
A28: Total project cost (₹) | B28: =E25 -> 29557500
A29: Promoter equity (₹) | B29: =B28*Inputs!$B$120 -> 7389375
A30: Term loan (₹) | B30: =B28-B29 -> 22168125
A31: MIDH subsidy adjusted against loan (₹) | B31: =H25 -> 4655000
A32: Net loan to service (₹) | B32: =B30-B31 -> 17513125
A33: Effective rate after AIF subvention | B33: =(MIN(B32,Inputs!$B$123)*(Inputs!$B$121-Inputs!$B$122)+MAX(0,B32-Inputs!$B$123)*Inputs!$B$121)/B32 -> 0.075
A34: Annual EMI (₹) | B34: =PMT(B33,Inputs!$B$124,-B32) -> 3306483.5
A35: Average annual interest (₹) | B35: =(B34*Inputs!$B$124-B32)/Inputs!$B$124 -> 804608.52
A37: Comparison with your Sitpur DPR (₹ lakh)
A38: DPR line | B38: DPR ₹ L | C38: This model ₹ L | D38: Comment
A39: Civil works + grading/sorting/packing line | B39: 68 | C39: =('Packhouse Capex'!$E$10)/100000 -> 122.5 | D39: Model uses a ₹90 L integrated packhouse listing + multi-fruit line
A40: Ripening chamber (20–25 MT) | B40: 45 | C40: 0 | D40: Not in model – you sell green, pre-ripened fruit. Add back if you ripen for quick-commerce.
A41: Pre-cooling unit & cold storage (20–25 MT) | B41: 28 | C41: =('Packhouse Capex'!$E$13+'Packhouse Capex'!$E$16)/100000 -> 112 | D41: Model: 3 × 6 MT pre-cooling + 100 MT cold storage (multi-fruit + export staging)
A42: Utilities & support | B42: 8 | C42: =('Packhouse Capex'!$E$23)/100000 -> 47
A43: Collection vehicles & material handling | B43: 15 | C43: 0 | D43: Model hires collection transport (₹/kg) instead
...

Sheet Packhouse Opex
A1: Opex by cost centre – packhouse lines, PRE-COOLING, COLD STORAGE, common (all driven by running days)
A2: Change running days on Inputs: day-based labour and energy move with them. Wages for harvest/loading are capped at ₹1,000/day.
A4: Item | B4: Driver | C4: Driver unit | D4: Rate | E4: Rate unit | F4: Annual cost (₹) | G4: Cost centre | H4: Confidence | I4: Note
A5: Variable / day-driven
A6: Harvest crew (13 people per 13 t) | B6: ='Operations & Capacity'!$B$35 -> 437.24696 | C6: crew-days | D6: =(Inputs!$B$38+Inputs!$B$39)*MIN(Inputs!$B$40,Inputs!$B$36) -> 13000 | E6: ₹/crew-day (capped) | F6: =B6*D6 -> 5684210.5 | G6: Harvest | H6: User | I6: Whole banana harvest
A7: Loading / unloading crew | B7: =Inputs!$B$8 -> 300 | C7: running days | D7: =Inputs!$B$41*MIN(Inputs!$B$42,Inputs!$B$36) -> 6400 | E7: ₹/day (capped) | F7: =B7*D7 -> 1920000 | G7: Packhouse | H7: Estimate
A8: Banana line workers | B8: ='Operations & Capacity'!$B$6 -> 300 | C8: running days | D8: =Inputs!$B$43*Inputs!$B$45 -> 15375 | E8: ₹/day | F8: =B8*D8 -> 4612500 | G8: Packhouse | H8: Researched | I8: [S6]
A9: Multi-fruit line workers | B9: ='Operations & Capacity'!$E$36 -> 300 | C9: line days | D9: =Inputs!$B$44*Inputs!$B$45 -> 6150 | E9: ₹/day | F9: =B9*D9 -> 1845000 | G9: Packhouse | H9: Researched | I9: [S6]
A10: Chemicals, sanitation & water | B10: ='Operations & Capacity'!$E$16*1000 -> 7029473.7 | C10: kg fruit | D10: =Inputs!$B$65+Inputs!$B$66 -> 0.45 | E10: ₹/kg | F10: =B10*D10 -> 3163263.2 | G10: Packhouse | H10: User/Est.
A11: Packing-line power | B11: =Inputs!$B$8 -> 300 | C11: running days | D11: =Inputs!$B$49*Inputs!$B$50*Inputs!$B$51*Inputs!$B$48 -> 1530 | E11: ₹/day | F11: =B11*D11 -> 459000 | G11: Packhouse | H11: Estimate
A12: PRE-COOLING power – product load | B12: ='Operations & Capacity'!$E$18 -> 6304.9263 | C12: t cooled | D12: =Inputs!$B$52*Inputs!$B$48 -> 170 | E12: ₹/t | F12: =B12*D12 -> 1071837.5 | G12: Pre-cooling | H12: Derived
A13: PRE-COOLING power – fans/standby | B13: =Inputs!$B$9 -> 300 | C13: running days | D13: =Inputs!$B$13*Inputs!$B$53*Inputs!$B$48 -> 255 | E13: ₹/day | F13: =B13*D13 -> 76500 | G13: Pre-cooling | H13: Estimate
A14: COLD STORAGE power | B14: =Inputs!$B$10 -> 330 | C14: running days | D14: =Inputs!$B$16*Inputs!$B$54*Inputs!$B$48 -> 2550 | E14: ₹/day | F14: =B14*D14 -> 841500 | G14: Cold storage | H14: Derived | I14: [S33]
A15: Fixed
A16: Packhouse manager (1) | B16: 1 | C16: headcount | D16: =60000*12*(1+Inputs!$B$46) -> 813600 | E16: ₹/yr incl. statutory | F16: =B16*D16 -> 813600 | G16: Packhouse | H16: Estimate
A17: QA / food safety & documentation (1) | B17: 1 | C17: headcount | D17: =35000*12*(1+Inputs!$B$46) -> 474600 | E17: ₹/yr incl. statutory | F17: =B17*D17 -> 474600 | G17: Packhouse | H17: Estimate
A18: Shift / labour supervisors (2) | B18: 2 | C18: headcount | D18: =25000*12*(1+Inputs!$B$46) -> 339000 | E18: ₹/yr incl. statutory | F18: =B18*D18 -> 678000 | G18: Packhouse | H18: Estimate
A19: Pre-cooling operator (1) | B19: 1 | C19: headcount | D19: =22000*12*(1+Inputs!$B$46) -> 298320 | E19: ₹/yr incl. statutory | F19: =B19*D19 -> 298320 | G19: Pre-cooling | H19: Estimate
A20: Cold storage / refrigeration technician (2) | B20: 2 | C20: headcount | D20: =22000*12*(1+Inputs!$B$46) -> 298320 | E20: ₹/yr incl. statutory | F20: =B20*D20 -> 596640 | G20: Cold storage | H20: Estimate
A21: Accounts & admin (1) | B21: 1 | C21: headcount | D21: =25000*12*(1+Inputs!$B$46) -> 339000 | E21: ₹/yr incl. statutory | F21: =B21*D21 -> 339000 | G21: Common | H21: Estimate
A22: Security guards (3) | B22: 3 | C22: headcount | D22: =14000*12*(1+Inputs!$B$46) -> 189840 | E22: ₹/yr incl. statutory | F22: =B22*D22 -> 569520 | G22: Common | H22: Estimate
A23: Sales / key-account manager (1) | B23: 1 | C23: headcount | D23: =60000*12*(1+Inputs!$B$46) -> 813600 | E23: ₹/yr incl. statutory | F23: =B23*D23 -> 813600 | G23: Common | H23: Estimate
A24: Electricity demand charges | B24: =Inputs!$B$55 -> 200 | C24: kW | D24: =Inputs!$B$56*12 -> 1800 | E24: ₹/kW/yr | F24: =B24*D24 -> 360000 | G24: Common | H24: Estimate
A25: R&M – packhouse lines | B25: ='Packhouse Capex'!$E$10 -> 12250000 | C25: ₹ capex | D25: 0.02 | E25: % of capex | F25: =B25*D25 -> 245000 | G25: Packhouse | H25: Estimate | I25: Refrigeration needs more upkeep
A26: R&M – pre-cooling | B26: ='Packhouse Capex'!$E$13 -> 9000000 | C26: ₹ capex | D26: 0.04 | E26: % of capex | F26: =B26*D26 -> 360000 | G26: Pre-cooling | H26: Estimate | I26: Refrigeration needs more upkeep
A27: R&M – cold storage | B27: ='Packhouse Capex'!$E$16 -> 2200000 | C27: ₹ capex | D27: 0.04 | E27: % of capex | F27: =B27*D27 -> 88000 | G27: Cold storage | H27: Estimate | I27: Refrigeration needs more upkeep
A28: R&M – common services | B28: ='Packhouse Capex'!$E$23 -> 4700000 | C28: ₹ capex | D28: 0.02 | E28: % of capex | F28: =B28*D28 -> 94000 | G28: Common | H28: Estimate | I28: Refrigeration needs more upkeep
A29: Insurance (fire, machinery, stock) | B29: ='Packhouse Capex'!$E$25 -> 29557500 | C29: ₹ capex | D29: 0.0035 | E29: % of capex | F29: =B29*D29 -> 103451.25 | G29: Common | H29: Estimate
A30: Certifications: GlobalG.A.P., APEDA, FSSAI | B30: 1 | C30: lot | D30: 350000 | E30: ₹/yr | F30: =B30*D30 -> 350000 | G30: Common | H30: Estimate
A31: Packhouse site lease (4 acres at estate rent) | B31: 4 | C31: acres | D31: =Inputs!$B$29 -> 50000 | E31: ₹/acre/yr | F31: =B31*D31 -> 200000 | G31: Common | H31: Derived | I31: DPR: lease from the family – terms open
A32: Admin overheads | B32: 12 | C32: months | D32: 50000 | E32: ₹/month | F32: =B32*D32 -> 600000 | G32: Common | H32: Estimate
A34: Cost-centre summary
A35: Cost centre | B35: Opex (₹/yr) | C35: Depreciation (₹/yr) | D35: Interest share (₹/yr) | E35: Total (₹/yr) | F35: Tonnes through | G35: ₹ per kg through
A36: Harvest | B36: =SUMIF($G$5:$G$32,"Harvest",$F$5:$F$32) -> 5684210.5 | C36: 0 | D36: 0 | E36: =B36+C36+D36 -> 5684210.5 | F36: ='Farm Plan'!$D$40 -> 5684.2105 | G36: =IF(F36=0,0,E36/(F36*1000)) -> 1
A37: Packhouse | B37: =SUMIF($G$5:$G$32,"Packhouse",$F$5:$F$32) -> 14210963 | C37: ='Packhouse Capex'!$J$10 -> 1099642.9 | D37: ='Packhouse Capex'!$B$35*('Packhouse Capex'!$E$10)/'Packhouse Capex'!$E$25 -> 333467.12 | E37: =B37+C37+D37 -> 15644073 | F37: ='Operations & Capacity'!$E$11 -> 7484.2105 | G37: =IF(F37=0,0,E37/(F37*1000)) -> 2.090277
A38: Pre-cooling | B38: =SUMIF($G$5:$G$32,"Pre-cooling",$F$5:$F$32) -> 1806657.5 | C38: ='Packhouse Capex'!$J$13 -> 900000 | D38: ='Packhouse Capex'!$B$35*('Packhouse Capex'!$E$13)/'Packhouse Capex'!$E$25 -> 244996.25 | E38: =B38+C38+D38 -> 2951653.7 | F38: ='Operations & Capacity'!$E$18 -> 6304.9263 | G38: =IF(F38=0,0,E38/(F38*1000)) -> 0.46815039
A39: Cold storage | B39: =SUMIF($G$5:$G$32,"Cold storage",$F$5:$F$32) -> 1526140 | C39: ='Packhouse Capex'!$J$16 -> 220000 | D39: ='Packhouse Capex'!$B$35*('Packhouse Capex'!$E$16)/'Packhouse Capex'!$E$25 -> 59887.973 | E39: =B39+C39+D39 -> 1806028 | F39: ='Operations & Capacity'!$E$18 -> 6304.9263 | G39: =IF(F39=0,0,E39/(F39*1000)) -> 0.28644712
A40: Common | B40: =SUMIF($G$5:$G$32,"Common",$F$5:$F$32) -> 3429571.2 | C40: ='Packhouse Capex'!$J$23+'Packhouse Capex'!$J$24 -> 550750 | D40: ='Packhouse Capex'!$B$35*('Packhouse Capex'!$E$23+'Packhouse Capex'!$E$24)/'Packhouse Capex'!$E$25 -> 166257.18 | E40: =B40+C40+D40 -> 4146578.4 | F40: ='Operations & Capacity'!$E$19 -> 6210.3524 | G40: =IF(F40=0,0,E40/(F40*1000)) -> 0.6676881
A41: TOTAL | B41: =SUM(B36:B40) -> 26657542 | C41: =SUM(C36:C40) -> 2770392.9 | D41: =SUM(D36:D40) -> 804608.52 | E41: =SUM(E36:E40) -> 30232544
A43: The pre-cooling and cold-storage rows above are the full cost of owning and running them: power, operators, repairs, plus their share of depreciation and interest. Rent benchmark if outsourced: ~₹0.30/kg/day [S26].

Sheet Unit Economics
A1: Unit economics per kg of sellable fruit – banana export, banana domestic, papaya, Kesar mango
A2: Line-specific labour goes to its own fruit; pre-cooling, cold storage, loading and common costs are shared per kg. Includes a column per carton.
A4: Line item (₹/kg) | B4: Banana export | C4: Banana domestic | D4: Papaya | E4: Kesar mango | F4: How calculated
A5: Selling price | B5: =Inputs!$B$95*Inputs!$B$6/Inputs!$B$62 -> 51.692308 | C5: =Inputs!$B$108 -> 28 | D5: =Inputs!$B$80 -> 26 | E5: =Inputs!$B$90 -> 120 | F5: Export CIF US$/carton × FX ÷ 13 kg
A6: Variable costs
A7: Fruit cost (own farm incl. farm depreciation / procurement) | B7: ='Farm Plan'!$D$45*('Operations & Capacity'!$B$11/'Operations & Capacity'!$B$19) -> 8.9144159 | C7: ='Farm Plan'!$D$45*('Operations & Capacity'!$B$11/'Operations & Capacity'!$B$19) -> 8.9144159 | D7: =(Inputs!$B$77+Inputs!$B$78)/((1-Inputs!$B$79)*(1-Inputs!$B$60)) -> 14.997693 | E7: =(Inputs!$B$87+Inputs!$B$88)/((1-Inputs!$B$89)*(1-Inputs!$B$60)) -> 80.556169 | F7: Banana: farm ₹/kg bunch × bunch per sellable kg. Others: (buy + inbound) ÷ pack-out
A8: Harvest crew (≤ ₹1,000/day) | B8: ='Packhouse Opex'!$G$36*('Operations & Capacity'!$B$11/'Operations & Capacity'!$B$19) -> 1.2261213 | C8: ='Packhouse Opex'!$G$36*('Operations & Capacity'!$B$11/'Operations & Capacity'!$B$19) -> 1.2261213 | D8: =0 -> 0 | E8: =0 -> 0 | F8: Harvest centre ₹/kg bunch × bunch per sellable kg
A9: Line labour (own line) | B9: =IF(('Operations & Capacity'!$B$19*1000)=0,0,'Packhouse Opex'!$F$8/('Operations & Capacity'!$B$19*1000)) -> 0.99494634 | C9: =IF(('Operations & Capacity'!$B$19*1000)=0,0,'Packhouse Opex'!$F$8/('Operations & Capacity'!$B$19*1000)) -> 0.99494634 | D9: =IF((('Operations & Capacity'!$C$19+'Operations & Capacity'!$D$19)*1000)=0,0,'Packhouse Opex'!$F$9/(('Operations & Capacity'!$C$19+'Operations & Capacity'!$D$19)*1000)) -> 1.1718571 | E9: =IF((('Operations & Capacity'!$C$19+'Operations & Capacity'!$D$19)*1000)=0,0,'Packhouse Opex'!$F$9/(('Operations & Capacity'!$C$19+'Operations & Capacity'!$D$19)*1000)) -> 1.1718571 | F9: Banana line ÷ banana kg; multi-fruit line ÷ papaya+mango kg
A10: Loading/unloading, chemicals, line power, packhouse staff & R&M | B10: =(('Packhouse Opex'!$B$37-'Packhouse Opex'!$F$8-'Packhouse Opex'!$F$9)/('Operations & Capacity'!$E$19*1000)) -> 1.2484739 | C10: =(('Packhouse Opex'!$B$37-'Packhouse Opex'!$F$8-'Packhouse Opex'!$F$9)/('Operations & Capacity'!$E$19*1000)) -> 1.2484739 | D10: =(('Packhouse Opex'!$B$37-'Packhouse Opex'!$F$8-'Packhouse Opex'!$F$9)/('Operations & Capacity'!$E$19*1000)) -> 1.2484739 | E10: =(('Packhouse Opex'!$B$37-'Packhouse Opex'!$F$8-'Packhouse Opex'!$F$9)/('Operations & Capacity'!$E$19*1000)) -> 1.2484739 | F10: Rest of packhouse centre opex ÷ all sellable kg
A11: PRE-COOLING (power, operator, R&M) | B11: =('Packhouse Opex'!$B$38/('Operations & Capacity'!$E$19*1000)) -> 0.29091062 | C11: =('Packhouse Opex'!$B$38/('Operations & Capacity'!$E$19*1000)) -> 0.29091062 | D11: =('Packhouse Opex'!$B$38/('Operations & Capacity'!$E$19*1000)) -> 0.29091062 | E11: =('Packhouse Opex'!$B$38/('Operations & Capacity'!$E$19*1000)) -> 0.29091062 | F11: Pre-cooling centre opex ÷ all sellable kg
A12: COLD STORAGE (power, technicians, R&M) | B12: =('Packhouse Opex'!$B$39/('Operations & Capacity'!$E$19*1000)) -> 0.24574129 | C12: =('Packhouse Opex'!$B$39/('Operations & Capacity'!$E$19*1000)) -> 0.24574129 | D12: =('Packhouse Opex'!$B$39/('Operations & Capacity'!$E$19*1000)) -> 0.24574129 | E12: =('Packhouse Opex'!$B$39/('Operations & Capacity'!$E$19*1000)) -> 0.24574129 | F12: Cold-storage centre opex ÷ all sellable kg
A13: Packaging | B13: =(Inputs!$B$67+Inputs!$B$68+Inputs!$B$69+Inputs!$B$70)/Inputs!$B$62 -> 7.5384615 | C13: =(Inputs!$B$71+Inputs!$B$72+Inputs!$B$73)/Inputs!$B$62 -> 5.1538462 | D13: =(Inputs!$B$82+Inputs!$B$83)/Inputs!$B$81 -> 2 | E13: =(Inputs!$B$92+Inputs!$B$93)/Inputs!$B$91 -> 11.666667 | F13: ₹ per box ÷ kg per box
A14: Export residue test & container consumables | B14: =Inputs!$B$99/(Inputs!$B$62*Inputs!$B$63) -> 0.6993007 | C14: =0 -> 0 | D14: =0 -> 0 | E14: =0 -> 0
A15: Transport to port / to domestic buyer | B15: =Inputs!$B$96/(Inputs!$B$62*Inputs!$B$63) -> 2.997003 | C15: =((Inputs!$B$113*Inputs!$B$110+Inputs!$B$114*Inputs!$B$111+Inputs!$B$115*Inputs!$B$112)/Inputs!$B$109) -> 4.7555556 | D15: =(Inputs!$B$110+Inputs!$B$111)/2/Inputs!$B$109 -> 2.8333333 | E15: =((Inputs!$B$113*Inputs!$B$110+Inputs!$B$114*Inputs!$B$111+Inputs!$B$115*Inputs!$B$112)/Inputs!$B$109) -> 4.7555556 | F15: Export haulage; banana & mango use the Ahmedabad/Mumbai/Delhi mix; papaya (short shelf life) goes to Ahmedabad/Mumbai only
A16: Port THC, CHA, customs, phyto | B16: =(Inputs!$B$97+Inputs!$B$98)/(Inputs!$B$62*Inputs!$B$63) -> 2.0979021 | C16: =0 -> 0 | D16: =0 -> 0 | E16: =0 -> 0
A17: Ocean freight (base) | B17: =Inputs!$B$100*Inputs!$B$6/(Inputs!$B$62*Inputs!$B$63) -> 9.5904096 | C17: =0 -> 0 | D17: =0 -> 0 | E17: =0 -> 0
A18: Gulf war-risk surcharge | B18: =Inputs!$B$101*Inputs!$B$102*Inputs!$B$6/(Inputs!$B$62*Inputs!$B$63) -> 19.180819 | C18: =0 -> 0 | D18: =0 -> 0 | E18: =0 -> 0 | F18: Switch on Inputs
A19: Insurance, bank/forex, claims / trade schemes, receivables | B19: =B5*(Inputs!$B$103+Inputs!$B$104+Inputs!$B$105-N(Inputs!$B$106)) -> 2.0935385 | C19: =C5*(Inputs!$B$116+Inputs!$B$121*Inputs!$B$117/365) -> 1.2024658 | D19: =D5*(Inputs!$B$116+Inputs!$B$121*Inputs!$B$117/365) -> 1.1165753 | E19: =E5*(Inputs!$B$116+Inputs!$B$121*Inputs!$B$117/365) -> 5.1534247 | F19: % of price
A20: Total variable cost | B20: =SUM(B7:B19) -> 57.118044 | C20: =SUM(C7:C19) -> 24.032477 | D20: =SUM(D7:D19) -> 23.904584 | E20: =SUM(E7:E19) -> 105.0888
A21: Contribution | B21: =B5-B20 -> -5.4257362 | C21: =C5-C20 -> 3.9675232 | D21: =D5-D20 -> 2.0954157 | E21: =E5-E20 -> 14.911202
A22: Shared fixed & capital costs
A23: Common overheads (admin, security, sales, demand charges, insurance, certifications, site lease) | B23: =('Packhouse Opex'!$B$40/('Operations & Capacity'!$E$19*1000)) -> 0.55223456 | C23: =('Packhouse Opex'!$B$40/('Operations & Capacity'!$E$19*1000)) -> 0.55223456 | D23: =('Packhouse Opex'!$B$40/('Operations & Capacity'!$E$19*1000)) -> 0.55223456 | E23: =('Packhouse Opex'!$B$40/('Operations & Capacity'!$E$19*1000)) -> 0.55223456 | F23: Common centre ÷ all sellable kg
A24: Depreciation & interest – packhouse, pre-cooling, cold storage | B24: =(('Packhouse Opex'!$C$41+'Packhouse Opex'!$D$41)/('Operations & Capacity'!$E$19*1000)) -> 0.57565193 | C24: =(('Packhouse Opex'!$C$41+'Packhouse Opex'!$D$41)/('Operations & Capacity'!$E$19*1000)) -> 0.57565193 | D24: =(('Packhouse Opex'!$C$41+'Packhouse Opex'!$D$41)/('Operations & Capacity'!$E$19*1000)) -> 0.57565193 | E24: =(('Packhouse Opex'!$C$41+'Packhouse Opex'!$D$41)/('Operations & Capacity'!$E$19*1000)) -> 0.57565193 | F24: All centres ÷ all sellable kg
A25: TOTAL COST | B25: =B20+B23+B24 -> 58.24593 | C25: =C20+C23+C24 -> 25.160363 | D25: =D20+D23+D24 -> 25.032471 | E25: =E20+E23+E24 -> 106.21668
A26: NET MARGIN (₹/kg) | B26: =B5-B25 -> -6.5536227 | C26: =C5-C25 -> 2.8396367 | D26: =D5-D25 -> 0.96752918 | E26: =E5-E25 -> 13.783315 | F26: Pre-tax
A27: Net margin % | B27: =IF(B5=0,0,B26/B5) -> -0.12678139 | C27: =IF(C5=0,0,C26/C5) -> 0.1014156 | D27: =IF(D5=0,0,D26/D5) -> 0.037212661 | E27: =IF(E5=0,0,E26/E5) -> 0.11486096
A28: Net margin per box / carton (₹) | B28: =B26*Inputs!$B$62 -> -85.197096 | C28: =C26*Inputs!$B$62 -> 36.915277 | D28: =D26*Inputs!$B$81 -> 9.6752918 | E28: =E26*Inputs!$B$91 -> 41.349945 | F28: 13 kg banana · 10 kg papaya · 3 kg mango
A29: Sellable volume (t/yr) | B29: ='Operations & Capacity'!$B$20 -> 1158.9821 | C29: ='Operations & Capacity'!$B$21 -> 3476.9463 | D29: ='Operations & Capacity'!$C$19 -> 1248.192 | E29: ='Operations & Capacity'!$D$19 -> 326.232
A30: Net margin per year (₹) | B30: =B26*B29*1000 -> -7595531.5 | C30: =C26*C29*1000 -> 9873264.3 | D30: =D26*D29*1000 -> 1207662.2 | E30: =E26*E29*1000 -> 4496558.4
A31: Export breakeven CIF (US$ per 13 kg carton) | B31: =B25*Inputs!$B$62/Inputs!$B$6 -> 7.8874697
A32: Breakeven selling price (₹/kg) | B32: =B25 -> 58.24593 | C32: =C25 -> 25.160363 | D32: =D25 -> 25.032471 | E32: =E25 -> 106.21668
A33: Banana price needed to beat selling at farm gate (₹/kg) | B33: =(('Farm Plan'!$D$47*('Operations & Capacity'!$B$11/'Operations & Capacity'!$B$19))+B25-B7-B8-B19)/(1-(Inputs!$B$103+Inputs!$B$104+Inputs!$B$105-N(Inputs!$B$106)))*Inputs!$B$62/Inputs!$B$6 -> 8.8298853 | C33: =(('Farm Plan'!$D$47*('Operations & Capacity'!$B$11/'Operations & Capacity'!$B$19))+C25-C7-C8-C19)/(1-(Inputs!$B$116+Inputs!$B$121*Inputs!$B$117/365)) -> 31.732768 | F33: Price at which packing & selling nets the same per kg of bunch as the farm-gate price on Farm Plan (export column in US$/carton)
A35: Sensitivity – banana EXPORT net margin (₹/kg): CIF US$/carton (rows) × war-risk surcharge US$/reefer (columns)
A36: Export cost excl. surcharge & %-items | B36: =B25-B18-B19 -> 36.971573
A37: %-of-price items | B37: =Inputs!$B$103+Inputs!$B$104+Inputs!$B$105-N(Inputs!$B$106) -> 0.0405
A38: CIF US$/carton \ surcharge → | B38: 0 | C38: 1500 | D38: 3000 | E38: 4000 | F38: 4800
A39: 5 | B39: =$A39*Inputs!$B$6/Inputs!$B$62*(1-$B$37)-$B$36-B$38*Inputs!$B$6/(Inputs!$B$62*Inputs!$B$63) -> -1.5438805 | C39: =$A39*Inputs!$B$6/Inputs!$B$62*(1-$B$37)-$B$36-C$38*Inputs!$B$6/(Inputs!$B$62*Inputs!$B$63) -> -8.7366877 | D39: =$A39*Inputs!$B$6/Inputs!$B$62*(1-$B$37)-$B$36-D$38*Inputs!$B$6/(Inputs!$B$62*Inputs!$B$63) -> -15.929495 | E39: =$A39*Inputs!$B$6/Inputs!$B$62*(1-$B$37)-$B$36-E$38*Inputs!$B$6/(Inputs!$B$62*Inputs!$B$63) -> -20.7247 | F39: =$A39*Inputs!$B$6/Inputs!$B$62*(1-$B$37)-$B$36-F$38*Inputs!$B$6/(Inputs!$B$62*Inputs!$B$63) -> -24.560863
A40: 5.5 | B40: =$A40*Inputs!$B$6/Inputs!$B$62*(1-$B$37)-$B$36-B$38*Inputs!$B$6/(Inputs!$B$62*Inputs!$B$63) -> 1.9988888 | C40: =$A40*Inputs!$B$6/Inputs!$B$62*(1-$B$37)-$B$36-C$38*Inputs!$B$6/(Inputs!$B$62*Inputs!$B$63) -> -5.1939184 | D40: =$A40*Inputs!$B$6/Inputs!$B$62*(1-$B$37)-$B$36-D$38*Inputs!$B$6/(Inputs!$B$62*Inputs!$B$63) -> -12.386726 | E40: =$A40*Inputs!$B$6/Inputs!$B$62*(1-$B$37)-$B$36-E$38*Inputs!$B$6/(Inputs!$B$62*Inputs!$B$63) -> -17.18193 | F40: =$A40*Inputs!$B$6/Inputs!$B$62*(1-$B$37)-$B$36-F$38*Inputs!$B$6/(Inputs!$B$62*Inputs!$B$63) -> -21.018094
A41: 6 | B41: =$A41*Inputs!$B$6/Inputs!$B$62*(1-$B$37)-$B$36-B$38*Inputs!$B$6/(Inputs!$B$62*Inputs!$B$63) -> 5.541658 | C41: =$A41*Inputs!$B$6/Inputs!$B$62*(1-$B$37)-$B$36-C$38*Inputs!$B$6/(Inputs!$B$62*Inputs!$B$63) -> -1.6511492 | D41: =$A41*Inputs!$B$6/Inputs!$B$62*(1-$B$37)-$B$36-D$38*Inputs!$B$6/(Inputs!$B$62*Inputs!$B$63) -> -8.8439564 | E41: =$A41*Inputs!$B$6/Inputs!$B$62*(1-$B$37)-$B$36-E$38*Inputs!$B$6/(Inputs!$B$62*Inputs!$B$63) -> -13.639161 | F41: =$A41*Inputs!$B$6/Inputs!$B$62*(1-$B$37)-$B$36-F$38*Inputs!$B$6/(Inputs!$B$62*Inputs!$B$63) -> -17.475325
A42: 6.5 | B42: =$A42*Inputs!$B$6/Inputs!$B$62*(1-$B$37)-$B$36-B$38*Inputs!$B$6/(Inputs!$B$62*Inputs!$B$63) -> 9.0844272 | C42: =$A42*Inputs!$B$6/Inputs!$B$62*(1-$B$37)-$B$36-C$38*Inputs!$B$6/(Inputs!$B$62*Inputs!$B$63) -> 1.89162 | D42: =$A42*Inputs!$B$6/Inputs!$B$62*(1-$B$37)-$B$36-D$38*Inputs!$B$6/(Inputs!$B$62*Inputs!$B$63) -> -5.3011872 | E42: =$A42*Inputs!$B$6/Inputs!$B$62*(1-$B$37)-$B$36-E$38*Inputs!$B$6/(Inputs!$B$62*Inputs!$B$63) -> -10.096392 | F42: =$A42*Inputs!$B$6/Inputs!$B$62*(1-$B$37)-$B$36-F$38*Inputs!$B$6/(Inputs!$B$62*Inputs!$B$63) -> -13.932556
...

Sheet Waste Valorisation
A1: Waste streams – what can be sold, and the unit economics of each
A2: Banana culls → flour · pseudostem → fibre · sap → liquid fertiliser (blank) · stalks, papaya & mango culls → vermicompost.
A4: Item | B4: Value | C4: Unit | D4: Confidence | E4: Source / note
A5: A. Banana culls → green banana flour
A6: Banana culls available | B6: ='Operations & Capacity'!$B$17 -> 522.94737 | C6: t/yr | E6: Operations tab (only fruit that went through the packhouse)
A7: Share processed into flour | B7: 0.8 | C7: % | D7: Estimate
A8: Fresh : flour | B8: 5 | C8: kg per kg | D8: Researched | E8: [S27] 4:1–5:1
A9: Flour output | B9: =$B$6*$B$7*1000/$B$8 -> 83671.579 | C9: kg/yr
A10: Flour price (bulk B2B) | B10: 180 | C10: ₹/kg | D10: Derived | E10: [S27] ₹140–350/kg listings
A11: Drying energy | B11: 4 | C11: kWh/kg flour | D11: Estimate
A12: Labour | B12: 20 | C12: ₹/kg flour | D12: Estimate
A13: Packaging | B13: 8 | C13: ₹/kg flour | D13: Estimate
A14: Consumables & testing | B14: 5 | C14: ₹/kg flour | D14: Estimate
A15: Fixed: supervisor, FSSAI, marketing | B15: 600000 | C15: ₹/yr | D15: Estimate
A16: Capex: slicer, dryer, pulveriser, sealer | B16: 2500000 | C16: ₹ | D16: Estimate | E16: PMFME: 35% subsidy up to ₹10 L
A17: Life | B17: 10 | C17: years | D17: Estimate
A18: Alternative: sell culls as-is | B18: 8 | C18: ₹/kg | D18: Estimate | E18: [S20]
A19: Revenue | B19: =$B$9*$B$10 -> 15060884 | C19: ₹/yr
A20: Variable cost | B20: =$B$9*($B$11*Inputs!$B$48+$B$12+$B$13+$B$14) -> 5605995.8 | C20: ₹/yr
A21: EBITDA | B21: =$B$19-$B$20-$B$15 -> 8854888.4 | C21: ₹/yr
A22: Depreciation | B22: =$B$16/$B$17 -> 250000 | C22: ₹/yr
A23: Net profit | B23: =$B$21-$B$22 -> 8604888.4 | C23: ₹/yr
A24: Net margin per kg flour | B24: =IF($B$9=0,0,$B$23/$B$9) -> 102.84123 | C24: ₹/kg
A25: Gain vs selling culls as-is | B25: =$B$23-$B$6*$B$7*1000*$B$18 -> 5258025.3 | C25: ₹/yr
A26: B. Pseudostem → banana fibre
A27: Pseudostem biomass | B27: ='Operations & Capacity'!$B$25 -> 6821.0526 | C27: t/yr
A28: Share collected for fibre | B28: 0.3 | C28: % | D28: Estimate
A29: Fibre yield | B29: 0.01 | C29: % | D29: Researched | E29: [S28]
A30: Fibre output | B30: =$B$27*$B$28*$B$29*1000 -> 20463.158 | C30: kg/yr
A31: Raw fibre price | B31: 150 | C31: ₹/kg | D31: Researched | E31: [S29] ₹135–242/kg by grade
A32: Decorticator capacity | B32: 25 | C32: kg/machine/day | D32: Researched | E32: [S28]
A33: Working days | B33: 250 | C33: days/yr | D33: Estimate
A34: Machines | B34: =ROUNDUP($B$30/($B$32*$B$33),0) -> 4 | C34: machines
A35: Machine cost | B35: 500000 | C35: ₹/machine | D35: Researched | E35: [S28] US$3–8k
A36: Workers per machine | B36: 3 | C36: people | D36: Estimate
A37: Power | B37: 40 | C37: kWh/machine/day | D37: Estimate
A38: Collection & haulage | B38: 300 | C38: ₹/t pseudostem | D38: Estimate
A39: Consumables | B39: 5 | C39: ₹/kg fibre | D39: Estimate
A40: Revenue | B40: =$B$30*$B$31 -> 3069473.7 | C40: ₹/yr
A41: Operating cost | B41: =$B$34*$B$33*($B$36*Inputs!$B$45+$B$37*Inputs!$B$48)+$B$27*$B$28*$B$38+$B$30*$B$39 -> 2593710.5 | C41: ₹/yr
...

Sheet Annual P&L
A1: Consolidated annual P&L – Sitpur farm + multi-fruit packhouse + pre-cooling + cold storage + by-products
A2: Column B follows Inputs (war-risk surcharge ON = Sep-2026). Column D = normalised year with no surcharge.
A4: Line item (₹/yr) | B4: As set on Inputs | C4: ₹ per kg sellable | D4: Normalised (no surcharge) | E4: Note
A5: Revenue
A6: Banana export | B6: ='Unit Economics'!$B$5*('Operations & Capacity'!$B$20*1000) -> 59910460 | C6: =B6/('Operations & Capacity'!$E$19*1000) -> 9.6468695 | D6: =B6 -> 59910460
A7: Banana domestic premium | B7: ='Unit Economics'!$C$5*('Operations & Capacity'!$B$21*1000) -> 97354497 | C7: =B7/('Operations & Capacity'!$E$19*1000) -> 15.676163 | D7: =B7 -> 97354497
A8: Banana surplus sold at farm gate (not processed) | B8: ='Operations & Capacity'!$B$12*1000*'Farm Plan'!$D$47 -> 0 | C8: =B8/('Operations & Capacity'!$E$19*1000) -> 0 | D8: =B8 -> 0 | E8: Only if running days/capacity are too low
A9: Papaya | B9: ='Unit Economics'!$D$5*('Operations & Capacity'!$C$19*1000) -> 32452992 | C9: =B9/('Operations & Capacity'!$E$19*1000) -> 5.2256281 | D9: =B9 -> 32452992
A10: Kesar mango | B10: ='Unit Economics'!$E$5*('Operations & Capacity'!$D$19*1000) -> 39147840 | C10: =B10/('Operations & Capacity'!$E$19*1000) -> 6.3036423 | D10: =B10 -> 39147840
A11: Rotation crop (scenario) | B11: ='Crop Rotation'!$B$27 -> 0 | C11: =B11/('Operations & Capacity'!$E$19*1000) -> 0 | D11: =B11 -> 0
A12: By-products | B12: ='Waste Valorisation'!$B$70 -> 20294905 | C12: =B12/('Operations & Capacity'!$E$19*1000) -> 3.2679152 | D12: =B12 -> 20294905
A13: TOTAL REVENUE | B13: =SUM(B6:B12) -> 2.4916069e+08 | C13: =B13/('Operations & Capacity'!$E$19*1000) -> 40.120218 | D13: =SUM(D6:D12) -> 2.4916069e+08
A14: Operating costs
A15: Farm: inputs + fixed costs (owner plan) | B15: ='Farm Plan'!$D$43 -> 39413737 | C15: =B15/('Operations & Capacity'!$E$19*1000) -> 6.3464574 | D15: =B15 -> 39413737
A16: Papaya & mango procurement incl. inbound freight | B16: ='Operations & Capacity'!$C$11*1000*(Inputs!$B$77+Inputs!$B$78)+'Operations & Capacity'!$D$11*1000*(Inputs!$B$87+Inputs!$B$88) -> 45000000 | C16: =B16/('Operations & Capacity'!$E$19*1000) -> 7.2459656 | D16: =B16 -> 45000000
A17: Harvest crew (≤ ₹1,000/day) | B17: ='Packhouse Opex'!$B$36 -> 5684210.5 | C17: =B17/('Operations & Capacity'!$E$19*1000) -> 0.91527987 | D17: =B17 -> 5684210.5
A18: Packhouse lines opex (labour, loading, chemicals, power, staff, R&M) | B18: ='Packhouse Opex'!$B$37 -> 14210963 | C18: =B18/('Operations & Capacity'!$E$19*1000) -> 2.28827 | D18: =B18 -> 14210963
A19: PRE-COOLING opex | B19: ='Packhouse Opex'!$B$38 -> 1806657.5 | C19: =B19/('Operations & Capacity'!$E$19*1000) -> 0.29091062 | D19: =B19 -> 1806657.5
A20: COLD STORAGE opex | B20: ='Packhouse Opex'!$B$39 -> 1526140 | C20: =B20/('Operations & Capacity'!$E$19*1000) -> 0.24574129 | D20: =B20 -> 1526140
A21: Common overheads | B21: ='Packhouse Opex'!$B$40 -> 3429571.2 | C21: =B21/('Operations & Capacity'!$E$19*1000) -> 0.55223456 | D21: =B21 -> 3429571.2
A22: Packaging – all fruits | B22: ='Unit Economics'!$B$13*('Operations & Capacity'!$B$20*1000)+'Unit Economics'!$C$13*('Operations & Capacity'!$B$21*1000)+'Unit Economics'!$D$13*('Operations & Capacity'!$C$19*1000)+'Unit Economics'!$E$13*('Operations & Capacity'!$D$19*1000) -> 32959012 | C22: =B22/('Operations & Capacity'!$E$19*1000) -> 5.3071082 | D22: =B22 -> 32959012
A23: Banana export logistics excl. surcharge | B23: =('Unit Economics'!$B$14+'Unit Economics'!$B$15+'Unit Economics'!$B$16+'Unit Economics'!$B$17)*('Operations & Capacity'!$B$20*1000) -> 17830494 | C23: =B23/('Operations & Capacity'!$E$19*1000) -> 2.8710921 | D23: =B23 -> 17830494
A24: Gulf war-risk surcharge | B24: ='Unit Economics'!$B$18*('Operations & Capacity'!$B$20*1000) -> 22230226 | C24: =B24/('Operations & Capacity'!$E$19*1000) -> 3.5795434 | D24: =0 -> 0 | E24: Only difference between B and D
A25: Domestic reefer freight – all fruits | B25: ='Unit Economics'!$C$15*(('Operations & Capacity'!$B$21*1000)+('Operations & Capacity'!$C$19*1000)+('Operations & Capacity'!$D$19*1000)) -> 24022072 | C25: =B25/('Operations & Capacity'!$E$19*1000) -> 3.8680691 | D25: =B25 -> 24022072
